A()
terminate called after throwing an instance of 'std::exception'
  what():  std::exception
bash: line 7: 26683 Aborted                 (core dumped) ./a.out
