123123
terminate called after throwing an instance of 'std::exception'
  what():  std::exception
bash: line 7: 28568 Aborted                 (core dumped) ./a.out first second
